[debug] [2019-03-19T21:54:25.174Z] ----------------------------------------------------------------------
[debug] [2019-03-19T21:54:25.177Z] Command:       /usr/local/Cellar/node/11.6.0/bin/node /usr/local/bin/firebase functions:shell
[debug] [2019-03-19T21:54:25.177Z] CLI Version:   6.4.0
[debug] [2019-03-19T21:54:25.177Z] Platform:      darwin
[debug] [2019-03-19T21:54:25.177Z] Node Version:  v11.6.0
[debug] [2019-03-19T21:54:25.183Z] Time:          Tue Mar 19 2019 15:54:25 GMT-0600 (Mountain Daylight Time)
[debug] [2019-03-19T21:54:25.183Z] ----------------------------------------------------------------------
[debug] 
[debug] [2019-03-19T21:54:25.194Z] > command requires scopes: ["email","openid","https://www.googleapis.com/auth/cloudplatformprojects.readonly","https://www.googleapis.com/auth/firebase","https://www.googleapis.com/auth/cloud-platform"]
[debug] [2019-03-19T21:54:25.194Z] > authorizing via signed-in user
[debug] [2019-03-19T21:54:25.194Z] [iam] checking project crapmap-c5c7f for permissions ["firebase.projects.get"]
[debug] [2019-03-19T21:54:25.196Z] >>> HTTP REQUEST POST https://cloudresourcemanager.googleapis.com/v1/projects/crapmap-c5c7f:testIamPermissions  

[debug] [2019-03-19T21:54:25.679Z] <<< HTTP RESPONSE 200
[debug] [2019-03-19T21:54:26.728Z] Error: EACCES: permission denied, mkdir '/usr/local/lib/node_modules/firebase-tools/node_modules/@google-cloud/functions-emulator/logs'
    at Object.mkdirSync (fs.js:775:3)
    at Object.assertLogsPath (/usr/local/lib/node_modules/firebase-tools/node_modules/@google-cloud/functions-emulator/src/emulator/logs.js:65:10)
    at new Controller (/usr/local/lib/node_modules/firebase-tools/node_modules/@google-cloud/functions-emulator/src/cli/controller.js:77:32)
    at FunctionsEmulator.start (/usr/local/lib/node_modules/firebase-tools/lib/functionsEmulator.js:102:23)
    at Command.module.exports [as _action] (/usr/local/lib/node_modules/firebase-tools/lib/functionsShellCommandAction.js:13:10)
    at /usr/local/lib/node_modules/firebase-tools/lib/command.js:167:37
    at process.internalTickCallback (internal/process/next_tick.js:77:7)
[error] 
[error] Error: An unexpected error has occurred.
